<?xml version="1.0" encoding="UTF-8"?>
<testsuite name="org.example.MainTest" tests="2" skipped="0" failures="1" errors="0" timestamp="2023-02-27T10:53:34" hostname="DESKTOP-HAPLGAQ" time="0.011">
  <properties/>
  <testcase name="totalPriceFalse" classname="org.example.MainTest" time="0.009"/>
  <testcase name="totalPricePassed" classname="org.example.MainTest" time="0.002">
    <failure message="java.lang.AssertionError: expected:&lt;50&gt; but was:&lt;180&gt;" type="java.lang.AssertionError">java.lang.AssertionError: expected:&lt;50&gt; but was:&lt;180&gt;
	at org.junit.Assert.fail(Assert.java:89)
	at org.junit.Assert.failNotEquals(Assert.java:835)
	at org.junit.Assert.assertEquals(Assert.java:647)
	at org.junit.Assert.assertEquals(Assert.java:633)
	at org.example.MainTest.totalPricePassed(MainTest.java:49)
	at java.base/jdk.internal.reflect.NativeMethodAccessorImpl.invoke0(Native Method)
	at java.base/jdk.internal.reflect.NativeMethodAccessorImpl.invoke(NativeMethodAccessorImpl.java:77)
	at java.base/jdk.internal.reflect.DelegatingMethodAccessorImpl.invoke(DelegatingMethodAccessorImpl.java:43)
	at java.base/java.lang.reflect.Method.invoke(Method.java:568)
	at org.junit.runners.model.FrameworkMethod$1.runReflectiveCall(FrameworkMethod.java:59)
	at org.junit.internal.runners.model.ReflectiveCallable.run(ReflectiveCallable.java:12)
	at org.junit.runners.model.FrameworkMethod.invokeExplosively(FrameworkMethod.java:56)
	at org.junit.internal.runners.statements.InvokeMethod.evaluate(InvokeMethod.java:17)
	at org.junit.internal.runners.statements.FailOnTimeout$CallableStatement.call(FailOnTimeout.java:288)
	at org.junit.internal.runners.statements.FailOnTimeout$CallableStatement.call(FailOnTimeout.java:282)
	at java.base/java.util.concurrent.FutureTask.run(FutureTask.java:264)
	at java.base/java.lang.Thread.run(Thread.java:833)
</failure>
  </testcase>
  <system-out><![CDATA[Test passed: 
Test passed: 
]]></system-out>
  <system-err><![CDATA[]]></system-err>
</testsuite>
